<mujoco model="empty_floor">
  <compiler angle="radian" />

  <option timestep="0.001" gravity="0 0 -9.81" integrator="implicitfast" impratio="1">
      <flag contact="enable" energy="enable" gravity="enable" />
  </option>

  <visual>
    <rgba haze="0.15 0.25 0.35 1" />
    <global azimuth="120" elevation="-20" />
  </visual>

  <asset>
    <mesh name="table" file="F:\mujoco_learning\szc_mujoco\mujoco_benchmark\robopal_part\assets\scenes\../objects/table/table.STL" scale="1.0 1.0 0.66" />

    <texture type="skybox" builtin="gradient" rgb1="0.68 0.68 0.68" rgb2="0.3 0.3 0.3" width="512" height="3072" />
    <texture name="groundplane" type="2d" builtin="checker" mark="edge" rgb1="0.68 0.68 0.68" rgb2="0.8 0.8 0.8" markrgb="0.68 0.68 0.68" width="300" height="300" />
    <material name="groundplane" reflectance="0.2" shininess="0.0" specular="0.0" texrepeat="5 5" texture="groundplane" texuniform="true" />

    <texture name="wood" type="2d" file="F:\mujoco_learning\szc_mujoco\mujoco_benchmark\robopal_part/./assets/textures\wood.png" />
    <material name="wood" texture="wood" texrepeat="1 1" texuniform="true" rgba="0.68 0.68 0.68 1" />
  <material class="panda" name="white" rgba="1 1 1 1" />
    <material class="panda" name="off_white" rgba="0.901961 0.921569 0.929412 1" />
    <material class="panda" name="dark_grey" rgba="0.25 0.25 0.25 1" />
    <material class="panda" name="green" rgba="0 1 0 1" />
    <material class="panda" name="light_blue" rgba="0.039216 0.541176 0.780392 1" />

    
    <mesh name="0_link0_c" file="F:\mujoco_learning\szc_mujoco\mujoco_benchmark\robopal_part\assets\models\manipulators\Panda\meshes/link0.stl" />
    <mesh name="0_link1_c" file="F:\mujoco_learning\szc_mujoco\mujoco_benchmark\robopal_part\assets\models\manipulators\Panda\meshes/link1.stl" />
    <mesh name="0_link2_c" file="F:\mujoco_learning\szc_mujoco\mujoco_benchmark\robopal_part\assets\models\manipulators\Panda\meshes/link2.stl" />
    <mesh name="0_link3_c" file="F:\mujoco_learning\szc_mujoco\mujoco_benchmark\robopal_part\assets\models\manipulators\Panda\meshes/link3.stl" />
    <mesh name="0_link4_c" file="F:\mujoco_learning\szc_mujoco\mujoco_benchmark\robopal_part\assets\models\manipulators\Panda\meshes/link4.stl" />
    <mesh name="0_link5_c0" file="F:\mujoco_learning\szc_mujoco\mujoco_benchmark\robopal_part\assets\models\manipulators\Panda\meshes/link5_collision_0.obj" />
    <mesh name="0_link5_c1" file="F:\mujoco_learning\szc_mujoco\mujoco_benchmark\robopal_part\assets\models\manipulators\Panda\meshes/link5_collision_1.obj" />
    <mesh name="0_link5_c2" file="F:\mujoco_learning\szc_mujoco\mujoco_benchmark\robopal_part\assets\models\manipulators\Panda\meshes/link5_collision_2.obj" />
    <mesh name="0_link6_c" file="F:\mujoco_learning\szc_mujoco\mujoco_benchmark\robopal_part\assets\models\manipulators\Panda\meshes/link6.stl" />
    <mesh name="0_link7_c" file="F:\mujoco_learning\szc_mujoco\mujoco_benchmark\robopal_part\assets\models\manipulators\Panda\meshes/link7.stl" />

    
    <mesh file="F:\mujoco_learning\szc_mujoco\mujoco_benchmark\robopal_part\assets\models\manipulators\Panda\meshes/link0_0.obj" />
    <mesh file="F:\mujoco_learning\szc_mujoco\mujoco_benchmark\robopal_part\assets\models\manipulators\Panda\meshes/link0_1.obj" />
    <mesh file="F:\mujoco_learning\szc_mujoco\mujoco_benchmark\robopal_part\assets\models\manipulators\Panda\meshes/link0_2.obj" />
    <mesh file="F:\mujoco_learning\szc_mujoco\mujoco_benchmark\robopal_part\assets\models\manipulators\Panda\meshes/link0_3.obj" />
    <mesh file="F:\mujoco_learning\szc_mujoco\mujoco_benchmark\robopal_part\assets\models\manipulators\Panda\meshes/link0_4.obj" />
    <mesh file="F:\mujoco_learning\szc_mujoco\mujoco_benchmark\robopal_part\assets\models\manipulators\Panda\meshes/link0_5.obj" />
    <mesh file="F:\mujoco_learning\szc_mujoco\mujoco_benchmark\robopal_part\assets\models\manipulators\Panda\meshes/link0_7.obj" />
    <mesh file="F:\mujoco_learning\szc_mujoco\mujoco_benchmark\robopal_part\assets\models\manipulators\Panda\meshes/link0_8.obj" />
    <mesh file="F:\mujoco_learning\szc_mujoco\mujoco_benchmark\robopal_part\assets\models\manipulators\Panda\meshes/link0_9.obj" />
    <mesh file="F:\mujoco_learning\szc_mujoco\mujoco_benchmark\robopal_part\assets\models\manipulators\Panda\meshes/link0_10.obj" />
    <mesh file="F:\mujoco_learning\szc_mujoco\mujoco_benchmark\robopal_part\assets\models\manipulators\Panda\meshes/link0_11.obj" />
    <mesh file="F:\mujoco_learning\szc_mujoco\mujoco_benchmark\robopal_part\assets\models\manipulators\Panda\meshes/link1.obj" />
    <mesh file="F:\mujoco_learning\szc_mujoco\mujoco_benchmark\robopal_part\assets\models\manipulators\Panda\meshes/link2.obj" />
    <mesh file="F:\mujoco_learning\szc_mujoco\mujoco_benchmark\robopal_part\assets\models\manipulators\Panda\meshes/link3_0.obj" />
    <mesh file="F:\mujoco_learning\szc_mujoco\mujoco_benchmark\robopal_part\assets\models\manipulators\Panda\meshes/link3_1.obj" />
    <mesh file="F:\mujoco_learning\szc_mujoco\mujoco_benchmark\robopal_part\assets\models\manipulators\Panda\meshes/link3_2.obj" />
    <mesh file="F:\mujoco_learning\szc_mujoco\mujoco_benchmark\robopal_part\assets\models\manipulators\Panda\meshes/link3_3.obj" />
    <mesh file="F:\mujoco_learning\szc_mujoco\mujoco_benchmark\robopal_part\assets\models\manipulators\Panda\meshes/link4_0.obj" />
    <mesh file="F:\mujoco_learning\szc_mujoco\mujoco_benchmark\robopal_part\assets\models\manipulators\Panda\meshes/link4_1.obj" />
    <mesh file="F:\mujoco_learning\szc_mujoco\mujoco_benchmark\robopal_part\assets\models\manipulators\Panda\meshes/link4_2.obj" />
    <mesh file="F:\mujoco_learning\szc_mujoco\mujoco_benchmark\robopal_part\assets\models\manipulators\Panda\meshes/link4_3.obj" />
    <mesh file="F:\mujoco_learning\szc_mujoco\mujoco_benchmark\robopal_part\assets\models\manipulators\Panda\meshes/link5_0.obj" />
    <mesh file="F:\mujoco_learning\szc_mujoco\mujoco_benchmark\robopal_part\assets\models\manipulators\Panda\meshes/link5_1.obj" />
    <mesh file="F:\mujoco_learning\szc_mujoco\mujoco_benchmark\robopal_part\assets\models\manipulators\Panda\meshes/link5_2.obj" />
    <mesh file="F:\mujoco_learning\szc_mujoco\mujoco_benchmark\robopal_part\assets\models\manipulators\Panda\meshes/link6_0.obj" />
    <mesh file="F:\mujoco_learning\szc_mujoco\mujoco_benchmark\robopal_part\assets\models\manipulators\Panda\meshes/link6_1.obj" />
    <mesh file="F:\mujoco_learning\szc_mujoco\mujoco_benchmark\robopal_part\assets\models\manipulators\Panda\meshes/link6_2.obj" />
    <mesh file="F:\mujoco_learning\szc_mujoco\mujoco_benchmark\robopal_part\assets\models\manipulators\Panda\meshes/link6_3.obj" />
    <mesh file="F:\mujoco_learning\szc_mujoco\mujoco_benchmark\robopal_part\assets\models\manipulators\Panda\meshes/link6_4.obj" />
    <mesh file="F:\mujoco_learning\szc_mujoco\mujoco_benchmark\robopal_part\assets\models\manipulators\Panda\meshes/link6_5.obj" />
    <mesh file="F:\mujoco_learning\szc_mujoco\mujoco_benchmark\robopal_part\assets\models\manipulators\Panda\meshes/link6_6.obj" />
    <mesh file="F:\mujoco_learning\szc_mujoco\mujoco_benchmark\robopal_part\assets\models\manipulators\Panda\meshes/link6_7.obj" />
    <mesh file="F:\mujoco_learning\szc_mujoco\mujoco_benchmark\robopal_part\assets\models\manipulators\Panda\meshes/link6_8.obj" />
    <mesh file="F:\mujoco_learning\szc_mujoco\mujoco_benchmark\robopal_part\assets\models\manipulators\Panda\meshes/link6_9.obj" />
    <mesh file="F:\mujoco_learning\szc_mujoco\mujoco_benchmark\robopal_part\assets\models\manipulators\Panda\meshes/link6_10.obj" />
    <mesh file="F:\mujoco_learning\szc_mujoco\mujoco_benchmark\robopal_part\assets\models\manipulators\Panda\meshes/link6_11.obj" />
    <mesh file="F:\mujoco_learning\szc_mujoco\mujoco_benchmark\robopal_part\assets\models\manipulators\Panda\meshes/link6_12.obj" />
    <mesh file="F:\mujoco_learning\szc_mujoco\mujoco_benchmark\robopal_part\assets\models\manipulators\Panda\meshes/link6_13.obj" />
    <mesh file="F:\mujoco_learning\szc_mujoco\mujoco_benchmark\robopal_part\assets\models\manipulators\Panda\meshes/link6_14.obj" />
    <mesh file="F:\mujoco_learning\szc_mujoco\mujoco_benchmark\robopal_part\assets\models\manipulators\Panda\meshes/link6_15.obj" />
    <mesh file="F:\mujoco_learning\szc_mujoco\mujoco_benchmark\robopal_part\assets\models\manipulators\Panda\meshes/link6_16.obj" />
    <mesh file="F:\mujoco_learning\szc_mujoco\mujoco_benchmark\robopal_part\assets\models\manipulators\Panda\meshes/link7_0.obj" />
    <mesh file="F:\mujoco_learning\szc_mujoco\mujoco_benchmark\robopal_part\assets\models\manipulators\Panda\meshes/link7_1.obj" />
    <mesh file="F:\mujoco_learning\szc_mujoco\mujoco_benchmark\robopal_part\assets\models\manipulators\Panda\meshes/link7_2.obj" />
    <mesh file="F:\mujoco_learning\szc_mujoco\mujoco_benchmark\robopal_part\assets\models\manipulators\Panda\meshes/link7_3.obj" />
    <mesh file="F:\mujoco_learning\szc_mujoco\mujoco_benchmark\robopal_part\assets\models\manipulators\Panda\meshes/link7_4.obj" />
    <mesh file="F:\mujoco_learning\szc_mujoco\mujoco_benchmark\robopal_part\assets\models\manipulators\Panda\meshes/link7_5.obj" />
    <mesh file="F:\mujoco_learning\szc_mujoco\mujoco_benchmark\robopal_part\assets\models\manipulators\Panda\meshes/link7_6.obj" />
    <mesh file="F:\mujoco_learning\szc_mujoco\mujoco_benchmark\robopal_part\assets\models\manipulators\Panda\meshes/link7_7.obj" />
  <material class="panda_hand" name="white_hand" rgba="1 1 1 1" />
    <material class="panda_hand" name="off_white_hand" rgba="0.901961 0.921569 0.929412 1" />
    <material class="panda_hand" name="black_hand" rgba="0.25 0.25 0.25 1" />

    
    <mesh name="0_hand_c" file="F:\mujoco_learning\szc_mujoco\mujoco_benchmark\robopal_part\assets\models\grippers\PandaHand\meshes/hand.stl" />

    
    <mesh file="F:\mujoco_learning\szc_mujoco\mujoco_benchmark\robopal_part\assets\models\grippers\PandaHand\meshes/hand_0.obj" />
    <mesh file="F:\mujoco_learning\szc_mujoco\mujoco_benchmark\robopal_part\assets\models\grippers\PandaHand\meshes/hand_1.obj" />
    <mesh file="F:\mujoco_learning\szc_mujoco\mujoco_benchmark\robopal_part\assets\models\grippers\PandaHand\meshes/hand_2.obj" />
    <mesh file="F:\mujoco_learning\szc_mujoco\mujoco_benchmark\robopal_part\assets\models\grippers\PandaHand\meshes/hand_3.obj" />
    <mesh file="F:\mujoco_learning\szc_mujoco\mujoco_benchmark\robopal_part\assets\models\grippers\PandaHand\meshes/hand_4.obj" />
    <mesh file="F:\mujoco_learning\szc_mujoco\mujoco_benchmark\robopal_part\assets\models\grippers\PandaHand\meshes/finger_0.obj" />
    <mesh file="F:\mujoco_learning\szc_mujoco\mujoco_benchmark\robopal_part\assets\models\grippers\PandaHand\meshes/finger_1.obj" />
  </asset>

  <worldbody>

    <geom condim="3" material="groundplane" name="floor" pos="0 0 0" size="3 3 .125" type="plane" />
    <light diffuse=".8 .8 .8" dir="0 -.15 -1" directional="false" pos="1 1 8.0" specular="0.3 0.3 0.3" castshadow="false" />
    <light diffuse=".8 .8 .8" dir="0 -.15 -1" directional="false" pos="-3. -3. 8.0" specular="0.3 0.3 0.3" castshadow="false" />
    
    <camera mode="fixed" name="frontview" pos="1.3 0 0.9" quat="0.56 0.43 0.43 0.56" />
    
    <camera mode="fixed" name="birdview" pos="-0.2 0 3.0" quat="0.7071 0 0 0.7071" />
    
    <camera mode="fixed" name="agentview" pos="0.5 0 1.35" quat="0.653 0.271 0.271 0.653" />
    
    <camera mode="fixed" name="sideview" pos="-0.05651774593317116 1.2761224129427358 1.4879572214102434" quat="0.009905065491771751 0.006877963156909582 0.5912228352893879 0.806418094001364" />

    <body name="table" pos="1.0 0.3 0.0">
        <include file="objects/table/table.xml" />
    </body>

  <body name="0_mount_base_link" pos="0 0 0.42">
            <geom type="sphere" size="0.01" contype="0" conaffinity="0" group="1" pos="0 0 0" rgba="1 1 1 1" />
        <body name="0_link0" childclass="panda">
      <inertial mass="0.629769" pos="-0.041018 -0.00014 0.049974" fullinertia="0.00315 0.00388 0.004285 8.2904e-7 0.00015 8.2299e-6" />
      <geom mesh="link0_0" material="off_white" class="panda/visual" />
      <geom mesh="link0_1" material="dark_grey" class="panda/visual" />
      <geom mesh="link0_2" material="off_white" class="panda/visual" />
      <geom mesh="link0_3" material="dark_grey" class="panda/visual" />
      <geom mesh="link0_4" material="off_white" class="panda/visual" />
      <geom mesh="link0_5" material="dark_grey" class="panda/visual" />
      <geom mesh="link0_7" material="white" class="panda/visual" />
      <geom mesh="link0_8" material="white" class="panda/visual" />
      <geom mesh="link0_9" material="dark_grey" class="panda/visual" />
      <geom mesh="link0_10" material="off_white" class="panda/visual" />
      <geom mesh="link0_11" material="white" class="panda/visual" />
      <geom mesh="0_link0_c" class="panda/collision" />
      <body name="0_link1" pos="0 0 0.333">
        <inertial mass="4.970684" pos="0.003875 0.002081 -0.04762" fullinertia="0.70337 0.70661 0.0091170 -0.00013900 0.0067720 0.019169" />
        <joint name="0_joint1" pos="0 0 0" axis="0 0 1" limited="true" range="-2.8973 2.8973" damping="0.1" />
        <geom material="white" mesh="link1" class="panda/visual" />
        <geom mesh="0_link1_c" class="panda/collision" />
        <body name="0_link2" quat="1 -1 0 0">
          <inertial mass="0.646926" pos="-0.003141 -0.02872 0.003495" fullinertia="0.0079620 2.8110e-2 2.5995e-2 -3.925e-3 1.0254e-2 7.04e-4" />
          <joint name="0_joint2" pos="0 0 0" axis="0 0 1" limited="true" range="-1.7628 1.7628" damping="0.1" />
          <geom material="white" mesh="link2" class="panda/visual" />
          <geom mesh="0_link2_c" class="panda/collision" />
          <body name="0_link3" pos="0 -0.316 0" quat="1 1 0 0">
            <joint name="0_joint3" pos="0 0 0" axis="0 0 1" limited="true" range="-2.8973 2.8973" damping="0.1" />
            <inertial mass="3.228604" pos="2.7518e-2 3.9252e-2 -6.6502e-2" fullinertia="3.7242e-2 3.6155e-2 1.083e-2 -4.761e-3 -1.1396e-2 -1.2805e-2" />
            <geom mesh="link3_0" material="white" class="panda/visual" />
            <geom mesh="link3_1" material="white" class="panda/visual" />
            <geom mesh="link3_2" material="white" class="panda/visual" />
            <geom mesh="link3_3" material="dark_grey" class="panda/visual" />
            <geom mesh="0_link3_c" class="panda/collision" />
            <body name="0_link4" pos="0.0825 0 0" quat="1 1 0 0">
              <inertial mass="3.587895" pos="-5.317e-2 1.04419e-1 2.7454e-2" fullinertia="2.5853e-2 1.9552e-2 2.8323e-2 7.796e-3 -1.332e-3 8.641e-3" />
              <joint name="0_joint4" pos="0 0 0" axis="0 0 1" limited="true" range="-3.0718 -0.0698" damping="0.1" />
              <geom mesh="link4_0" material="white" class="panda/visual" />
              <geom mesh="link4_1" material="white" class="panda/visual" />
              <geom mesh="link4_2" material="dark_grey" class="panda/visual" />
              <geom mesh="link4_3" material="white" class="panda/visual" />
              <geom mesh="0_link4_c" class="panda/collision" />
              <body name="0_link5" pos="-0.0825 0.384 0" quat="1 -1 0 0">
                <inertial mass="1.225946" pos="-1.1953e-2 4.1065e-2 -3.8437e-2" fullinertia="3.5549e-2 2.9474e-2 8.627e-3 -2.117e-3 -4.037e-3 2.29e-4" />
                <joint name="0_joint5" pos="0 0 0" axis="0 0 1" limited="true" range="-2.8973 2.8973" damping="0.1" />
                <geom mesh="link5_0" material="dark_grey" class="panda/visual" />
                <geom mesh="link5_1" material="white" class="panda/visual" />
                <geom mesh="link5_2" material="white" class="panda/visual" />
                <geom mesh="0_link5_c0" class="panda/collision" />
                <geom mesh="0_link5_c1" class="panda/collision" />
                <geom mesh="0_link5_c2" class="panda/collision" />
                <body name="0_link6" quat="1 1 0 0">
                  <inertial mass="1.666555" pos="6.0149e-2 -1.4117e-2 -1.0517e-2" fullinertia="1.964e-3 4.354e-3 5.433e-3 1.09e-4 -1.158e-3 3.41e-4" />
                  <joint name="0_joint6" pos="0 0 0" axis="0 0 1" limited="true" range="-0.0175 3.7525" damping="0.01" />
                  <geom mesh="link6_0" material="off_white" class="panda/visual" />
                  <geom mesh="link6_1" material="white" class="panda/visual" />
                  <geom mesh="link6_2" material="dark_grey" class="panda/visual" />
                  <geom mesh="link6_3" material="white" class="panda/visual" />
                  <geom mesh="link6_4" material="white" class="panda/visual" />
                  <geom mesh="link6_5" material="white" class="panda/visual" />
                  <geom mesh="link6_6" material="white" class="panda/visual" />
                  <geom mesh="link6_7" material="light_blue" class="panda/visual" />
                  <geom mesh="link6_8" material="light_blue" class="panda/visual" />
                  <geom mesh="link6_9" material="dark_grey" class="panda/visual" />
                  <geom mesh="link6_10" material="dark_grey" class="panda/visual" />
                  <geom mesh="link6_11" material="white" class="panda/visual" />
                  <geom mesh="link6_12" material="green" class="panda/visual" />
                  <geom mesh="link6_13" material="white" class="panda/visual" />
                  <geom mesh="link6_14" material="dark_grey" class="panda/visual" />
                  <geom mesh="link6_15" material="dark_grey" class="panda/visual" />
                  <geom mesh="link6_16" material="white" class="panda/visual" />
                  <geom mesh="0_link6_c" class="panda/collision" />
                  <body name="0_link7" pos="0.088 0 0" quat="1 1 0 0">
                    <inertial mass="7.35522e-01" pos="1.0517e-2 -4.252e-3 6.1597e-2" fullinertia="1.2516e-2 1.0027e-2 4.815e-3 -4.28e-4 -1.196e-3 -7.41e-4" />
                    <joint name="0_joint7" pos="0 0 0" axis="0 0 1" limited="true" range="-2.8973 2.8973" damping="0.01" />
                    <geom mesh="link7_0" material="white" class="panda/visual" />
                    <geom mesh="link7_1" material="dark_grey" class="panda/visual" />
                    <geom mesh="link7_2" material="dark_grey" class="panda/visual" />
                    <geom mesh="link7_3" material="dark_grey" class="panda/visual" />
                    <geom mesh="link7_4" material="dark_grey" class="panda/visual" />
                    <geom mesh="link7_5" material="dark_grey" class="panda/visual" />
                    <geom mesh="link7_6" material="dark_grey" class="panda/visual" />
                    <geom mesh="link7_7" material="white" class="panda/visual" />
                    <geom mesh="0_link7_c" class="panda/collision" />
                    <body name="0_attachment" pos="0 0 0.107" quat="0.3826834 0 0 0.9238795">
                      <site name="0_attachment_site" />
                    <body name="0_hand" childclass="panda_hand" quat="0 0 0 1">
      <inertial mass="0.73" pos="-0.01 0 0.03" diaginertia="0.001 0.0025 0.0017" />
      <geom mesh="hand_0" material="off_white_hand" class="visual" />
      <geom mesh="hand_1" material="black_hand" class="visual" />
      <geom mesh="hand_2" material="black_hand" class="visual" />
      <geom mesh="hand_3" material="white_hand" class="visual" />
      <geom mesh="hand_4" material="off_white_hand" class="visual" />
      <geom mesh="0_hand_c" class="collision" />
      
      <body name="0_eef" pos="0 0 0.1" quat="0 1 0 0">
          <site name="0_grip_site" pos="0 0 0" size="0.005" rgba="1 0 0 0.1" type="sphere" group="1" />
          <site name="0_ee_x" pos="0.2 0 0" size="0.005 .2" quat="0.707105  0 0.707108 0 " rgba="1 0 0 0.1" type="cylinder" group="1" />
          <site name="0_ee_y" pos="0 0.2 0" size="0.005 .2" quat="0.707105 0.707108 0 0" rgba="0 1 0 0.1" type="cylinder" group="1" />
          <site name="0_ee_z" pos="0 0 0.2" size="0.005 .2" quat="1 0 0 0" rgba="0 0 1 0.5" type="cylinder" group="1" />
          <site name="0_ee_x_ne" pos="-0.2 0 0" size="0.005 .2" quat="0.707105  0 0.707108 0 " rgba="1 1 1 0.1" type="cylinder" group="1" />
          <site name="0_ee_y_ne" pos="0 -0.2 0" size="0.005 .2" quat="0.707105 0.707108 0 0" rgba="1 1 1 0.1" type="cylinder" group="1" />
          <site name="0_ee_z_ne" pos="0 0 -0.2" size="0.005 .2" quat="1 0 0 0" rgba="1 1 1 0.1" type="cylinder" group="1" />
      </body>
      <body name="0_left_finger" pos="0 0 0.0584">
        <inertial mass="0.015" pos="0 0 0" diaginertia="2.375e-6 2.375e-6 7.5e-7" />
        <joint name="0_finger_joint1" class="finger" />
        <geom mesh="finger_0" material="off_white_hand" class="visual" />
        <geom mesh="finger_1" material="black_hand" class="visual" />
        <geom mesh="finger_0" class="collision" />
        <geom class="fingertip_pad_collision_1" />
        <geom class="fingertip_pad_collision_2" />
        <geom class="fingertip_pad_collision_3" />
        <geom class="fingertip_pad_collision_4" />
        <geom class="fingertip_pad_collision_5" />
      </body>
      <body name="0_right_finger" pos="0 0 0.0584" quat="0 0 0 1">
        <inertial mass="0.015" pos="0 0 0" diaginertia="2.375e-6 2.375e-6 7.5e-7" />
        <joint name="0_finger_joint2" class="finger" />
        <geom mesh="finger_0" material="off_white_hand" class="visual" />
        <geom mesh="finger_1" material="black_hand" class="visual" />
        <geom mesh="finger_0" class="collision" />
        <geom class="fingertip_pad_collision_1" />
        <geom class="fingertip_pad_collision_2" />
        <geom class="fingertip_pad_collision_3" />
        <geom class="fingertip_pad_collision_4" />
        <geom class="fingertip_pad_collision_5" />
      </body>
    </body>
  </body>
                  </body>
                </body>
              </body>
            </body>
          </body>
        </body>
      </body>
    </body>
  </body>
    </worldbody>
<actuator><motor ctrllimited="true" ctrlrange="-80.0 80.0" joint="0_joint1" name="0_actuator1" />
        <motor ctrllimited="true" ctrlrange="-80.0 80.0" joint="0_joint2" name="0_actuator2" />
        <motor ctrllimited="true" ctrlrange="-80.0 80.0" joint="0_joint3" name="0_actuator3" />
        <motor ctrllimited="true" ctrlrange="-80.0 80.0" joint="0_joint4" name="0_actuator4" />
        <motor ctrllimited="true" ctrlrange="-80.0 80.0" joint="0_joint5" name="0_actuator5" />
        <motor ctrllimited="true" ctrlrange="-12.0 12.0" joint="0_joint6" name="0_actuator6" />
        <motor ctrllimited="true" ctrlrange="-12.0 12.0" joint="0_joint7" name="0_actuator7" />
    <general class="panda_hand" name="0_actuator8" tendon="0_split" forcerange="-100 100" ctrlrange="0 255" gainprm="0.01568627451 0 0" biasprm="0 -100 -10" />
  </actuator><default><default class="panda">
      <material specular="0.5" shininess="0.25" />
      <joint armature="0.1" damping="1" axis="0 0 1" range="-2.8973 2.8973" />
      <general dyntype="none" biastype="affine" ctrlrange="-2.8973 2.8973" forcerange="-87 87" />

      <default class="panda/visual">
        <geom type="mesh" contype="0" conaffinity="0" group="2" />
      </default>
      <default class="panda/collision">
        <geom type="mesh" group="3" />
      </default>
      <site size="0.001" rgba="0.5 0.5 0.5 0.3" group="4" />
    </default>
  <default class="panda_hand">
      <material specular="0.5" shininess="0.25" />
      <joint armature="0.1" damping="1" axis="0 0 1" range="-2.8973 2.8973" />
      <general dyntype="none" biastype="affine" ctrlrange="-2.8973 2.8973" forcerange="-87 87" />
      <default class="finger">
        <joint axis="0 1 0" type="slide" range="0 0.04" />
      </default>

      <default class="visual">
        <geom type="mesh" contype="0" conaffinity="0" group="2" />
      </default>
      <default class="collision">
        <geom type="mesh" group="4" conaffinity="1" contype="0" condim="4" friction="1 1 1" solimp="1 1 1" />
        <default class="fingertip_pad_collision_1">
          <geom type="box" size="0.0085 0.004 0.0085" pos="0 0.0055 0.0445" />
        </default>
        <default class="fingertip_pad_collision_2">
          <geom type="box" size="0.003 0.002 0.003" pos="0.0055 0.002 0.05" />
        </default>
        <default class="fingertip_pad_collision_3">
          <geom type="box" size="0.003 0.002 0.003" pos="-0.0055 0.002 0.05" />
        </default>
        <default class="fingertip_pad_collision_4">
          <geom type="box" size="0.003 0.002 0.0035" pos="0.0055 0.002 0.0395" />
        </default>
        <default class="fingertip_pad_collision_5">
          <geom type="box" size="0.003 0.002 0.0035" pos="-0.0055 0.002 0.0395" />
        </default>
      </default>
    </default>
  </default><contact><exclude body1="0_hand" body2="0_left_finger" />
    <exclude body1="0_hand" body2="0_right_finger" />
  </contact><sensor /><equality><joint joint1="0_finger_joint1" joint2="0_finger_joint2" solimp="0.95 0.99 0.001" solref="0.005 1" />
  </equality><tendon><fixed name="0_split">
      <joint joint="0_finger_joint1" coef="0.5" />
      <joint joint="0_finger_joint2" coef="0.5" />
    </fixed>
  </tendon></mujoco>